## 📋 Issue #653 対応状況報告

### ✅ **解決完了した問題**

#### 1. dict属性エラー (convert_command.py:115)
- **修正内容**: `error_report.get("console_output")` の不正アクセスを修正
- **対応ファイル**: `kumihan_formatter/commands/convert/convert_command.py`
- **状況**: ✅ 完全解決

#### 2. convert_watcher.py の同様エラー
- **修正内容**: `error_report.has_errors()`, `error_report.has_warnings()`, `error_report.to_console_output()` を dict アクセスに変更
- **対応ファイル**: `kumihan_formatter/commands/convert/convert_watcher.py`
- **状況**: ✅ 完全解決

#### 3. 基本CLI変換機能の復旧
- **検証結果**: CLI基本機能が正常動作することを確認
- **テスト**: `python3 -m kumihan_formatter convert test.txt -o ./output --no-preview` で動作確認済み
- **状況**: ✅ 完全解決

#### 4. test_file_commandモジュール問題
- **調査結果**: 該当するモジュール参照は実際には存在しない
- **状況**: ✅ 完全解決（誤報）

---

### ❌ **残存する課題**

#### 🚨 記法バリデーションの不具合
**問題詳細**:
- 新記法のブロック形式 `#キーワード#...#` で不正なバリデーションエラーが発生
- 正しい記法でも「ブロック開始マーカーなしに # が見つかりました」エラー

**再現例**:
```
#テスト#
内容
#
```

**エラーメッセージ**:
```
エラー: ブロック開始マーカーなしに # が見つかりました
```

**原因分析**:
`kumihan_formatter/core/syntax/syntax_validator.py` の `_validate_syntax` メソッドで、新記法のブロック終了マーカー `#` が適切に認識されていない。

**影響**:
- ユーザーが正しい新記法を使用してもバリデーションエラーで変換が中止される
- `--no-syntax-check` オプションでの回避は可能だが、根本解決が必要

**技術的詳細**:
- 18-27行目のロジックで単独 `#` の判定に問題
- インライン記法とブロック記法の判定ロジックの整合性に課題

---

### 📊 **対応完了率**
- **解決済み**: 75% (3/4 の主要問題)
- **残存**: 25% (記法バリデーション問題)

### 🔧 **次のアクション**
記法バリデーションの修正には記法仕様の詳細な理解が必要です。Issue #652 (記法仕様の根本的見直し) との関連も考慮して対応方針を検討する必要があります。

**暫定対処法**: `--no-syntax-check` オプションを使用することで変換処理は実行可能です。