"""
エラー回復機能のテスト

Important Tier Phase 2-1対応 - Issue #593
エラー回復機能の体系的テスト実装
"""

from pathlib import Path
from unittest.mock import Mock, patch

import pytest

from kumihan_formatter.core.error_handling.error_recovery import ErrorRecovery
from kumihan_formatter.core.error_handling.error_types import (
    ErrorCategory,
    ErrorLevel,
    ErrorSolution,
    UserFriendlyError,
)


class TestErrorRecovery:
    """エラー回復機能のテストクラス"""

    def test_init(self):
        """初期化テスト"""
        # When
        recovery = ErrorRecovery()

        # Then
        assert recovery._recovery_attempts == 0
        assert recovery._max_attempts == 3

    def test_attempt_recovery_basic(self):
        """基本的な回復試行テスト"""
        # Given
        recovery = ErrorRecovery()
        error = UserFriendlyError(
            error_code="TEST_ERROR",
            level=ErrorLevel.ERROR,
            category=ErrorCategory.UNKNOWN,
            user_message="Test error",
            solution=ErrorSolution(quick_fix="Test fix", detailed_steps=["Step 1"]),
        )
        context = {"operation": "test"}

        # When
        result = recovery.attempt_recovery(error, context)

        # Then
        # 現在の実装では常にFalseを返す
        assert result is False

    def test_attempt_recovery_without_context(self):
        """コンテキストなしでの回復試行テスト"""
        # Given
        recovery = ErrorRecovery()
        error = UserFriendlyError(
            error_code="TEST_ERROR",
            level=ErrorLevel.ERROR,
            category=ErrorCategory.UNKNOWN,
            user_message="Test error",
            solution=ErrorSolution(quick_fix="Test fix", detailed_steps=["Step 1"]),
        )

        # When
        result = recovery.attempt_recovery(error)

        # Then
        assert result is False

    def test_can_auto_fix_basic(self):
        """基本的な自動修正可能性チェックテスト"""
        # Given
        recovery = ErrorRecovery()
        error = UserFriendlyError(
            error_code="TEST_ERROR",
            level=ErrorLevel.ERROR,
            category=ErrorCategory.UNKNOWN,
            user_message="Test error",
            solution=ErrorSolution(quick_fix="Test fix", detailed_steps=["Step 1"]),
        )

        # When
        result = recovery.can_auto_fix(error)

        # Then
        # 現在の実装では常にFalseを返す
        assert result is False

    def test_can_auto_fix_with_suggestions(self):
        """提案付きエラーの自動修正可能性チェックテスト"""
        # Given
        recovery = ErrorRecovery()
        error = UserFriendlyError(
            error_code="ENCODING_ERROR",
            level=ErrorLevel.ERROR,
            category=ErrorCategory.ENCODING,
            user_message="Encoding error",
            solution=ErrorSolution(
                quick_fix="Try different encoding",
                detailed_steps=["Try shift_jis encoding", "Try cp932 encoding"],
            ),
        )

        # When
        result = recovery.can_auto_fix(error)

        # Then
        assert result is False

    def test_recovery_attempts_tracking(self):
        """回復試行回数の追跡テスト"""
        # Given
        recovery = ErrorRecovery()
        error = UserFriendlyError(
            error_code="TEST_ERROR",
            level=ErrorLevel.ERROR,
            category=ErrorCategory.UNKNOWN,
            user_message="Test error",
            solution=ErrorSolution(quick_fix="Test fix", detailed_steps=["Step 1"]),
        )

        # When
        initial_attempts = recovery._recovery_attempts
        recovery.attempt_recovery(error)

        # Then
        # 現在の実装では試行回数は変更されない
        assert recovery._recovery_attempts == initial_attempts

    def test_max_attempts_limit(self):
        """最大試行回数の制限テスト"""
        # Given
        recovery = ErrorRecovery()
        recovery._recovery_attempts = recovery._max_attempts

        error = UserFriendlyError(
            error_code="TEST_ERROR",
            level=ErrorLevel.ERROR,
            category=ErrorCategory.UNKNOWN,
            user_message="Test error",
            solution=ErrorSolution(quick_fix="Test fix", detailed_steps=["Step 1"]),
        )

        # When
        result = recovery.attempt_recovery(error)

        # Then
        assert result is False
        # 最大試行回数に達していても現在の実装では特に処理されない

    def test_recover_with_fallback_integration(self):
        """recover_with_fallback統合テスト"""
        # Given
        recovery = ErrorRecovery()

        # Mock operation that fails
        operation = Mock(side_effect=ValueError("Operation failed"))
        fallback = Mock(return_value="fallback_result")

        # When
        # ErrorRecoveryクラスはrecover_with_fallbackメソッドを持たない
        # これは将来の拡張のためのテスト
        with pytest.raises(AttributeError):
            recovery.recover_with_fallback(operation, fallback)

    def test_future_encoding_error_recovery(self):
        """将来実装: エンコーディングエラーの回復テスト"""
        # Given
        recovery = ErrorRecovery()
        encoding_error = UserFriendlyError(
            error_code="ENCODING_ERROR",
            level=ErrorLevel.ERROR,
            category=ErrorCategory.ENCODING,
            user_message="Failed to decode file",
            solution=ErrorSolution(
                quick_fix="Try different encoding",
                detailed_steps=["Try shift_jis encoding"],
            ),
            context={
                "file_path": "test.txt",
                "detected_encoding": "shift_jis",
            },
        )

        # When
        can_fix = recovery.can_auto_fix(encoding_error)
        result = recovery.attempt_recovery(encoding_error)

        # Then
        # 将来の実装では、検出されたエンコーディングで再試行される
        assert can_fix is False  # 現在はFalse
        assert result is False  # 現在はFalse

    def test_future_syntax_error_recovery(self):
        """将来実装: 構文エラーの回復テスト"""
        # Given
        recovery = ErrorRecovery()
        syntax_error = UserFriendlyError(
            error_code="SYNTAX_ERROR",
            level=ErrorLevel.ERROR,
            category=ErrorCategory.SYNTAX,
            user_message="Invalid markdown syntax",
            solution=ErrorSolution(
                quick_fix="Fix syntax",
                detailed_steps=["Close decoration tags"],
            ),
            context={
                "line_number": 10,
                "line_content": ";;;unclosed",
                "suggested_fix": ";;;unclosed;;;",
            },
        )

        # When
        can_fix = recovery.can_auto_fix(syntax_error)
        result = recovery.attempt_recovery(syntax_error)

        # Then
        # 将来の実装では、提案された修正が適用される
        assert can_fix is False  # 現在はFalse
        assert result is False  # 現在はFalse

    def test_future_permission_error_recovery(self):
        """将来実装: 権限エラーの回復テスト"""
        # Given
        recovery = ErrorRecovery()
        permission_error = UserFriendlyError(
            error_code="PERMISSION_ERROR",
            level=ErrorLevel.ERROR,
            category=ErrorCategory.PERMISSION,
            user_message="Permission denied",
            solution=ErrorSolution(
                quick_fix="Use temporary file",
                detailed_steps=["Write to temporary location"],
            ),
            context={
                "file_path": "/protected/file.txt",
                "operation": "write",
                "temp_path": "/tmp/file.txt",
            },
        )

        # When
        can_fix = recovery.can_auto_fix(permission_error)
        result = recovery.attempt_recovery(permission_error)

        # Then
        # 将来の実装では、一時ファイルへの書き込みが試行される
        assert can_fix is False  # 現在はFalse
        assert result is False  # 現在はFalse

    def test_error_context_preservation(self):
        """エラーコンテキストの保持テスト"""
        # Given
        recovery = ErrorRecovery()
        context_data = {
            "file_path": "test.txt",
            "line_number": 42,
            "operation": "parse",
            "encoding": "utf-8",
        }
        error = UserFriendlyError(
            error_code="TEST_ERROR",
            level=ErrorLevel.ERROR,
            category=ErrorCategory.UNKNOWN,
            user_message="Test error",
            solution=ErrorSolution(quick_fix="Test fix", detailed_steps=["Step 1"]),
            context=context_data,
        )

        # When
        recovery.attempt_recovery(error, context_data)

        # Then
        # エラーとコンテキストが正しく渡されることを確認
        assert error.context == context_data

    def test_recovery_with_multiple_error_types(self):
        """複数のエラータイプでの回復テスト"""
        # Given
        recovery = ErrorRecovery()

        error_categories = [
            ErrorCategory.FILE_SYSTEM,
            ErrorCategory.PERMISSION,
            ErrorCategory.ENCODING,
            ErrorCategory.SYNTAX,
            ErrorCategory.SYSTEM,
        ]

        # When/Then
        for category in error_categories:
            error = UserFriendlyError(
                error_code=f"{category.value.upper()}_ERROR",
                level=ErrorLevel.ERROR,
                category=category,
                user_message=f"Error: {category.value}",
                solution=ErrorSolution(
                    quick_fix=f"Fix {category.value}",
                    detailed_steps=[f"Step for {category.value}"],
                ),
            )
            result = recovery.attempt_recovery(error)
            assert result is False  # 現在の実装では全てFalse

    def test_recovery_state_isolation(self):
        """回復状態の分離テスト"""
        # Given
        recovery1 = ErrorRecovery()
        recovery2 = ErrorRecovery()

        # Modify state of recovery1
        recovery1._recovery_attempts = 2

        # Then
        assert recovery2._recovery_attempts == 0
        assert recovery1._recovery_attempts == 2
